Workbook

Sheet Leggimi
A1: Kriné Labs · Modello di cassa mensile a 30 mesi
A3: A che cosa serve
A4: Calcola mese per mese la cassa della società dalla chiusura della raccolta al mese 30: spese di sviluppo, scorte,
A5: pubblicità, incassi, IVA, rimborsi della garanzia. Cassa minima e fabbisogno sono risultati, non ipotesi.
A7: Come si usa
A8: 1. Si modificano solo le celle in blu su fondo giallo del foglio Parametri e gli importi del foglio Progetto.
A9: 2. Ogni colonna di Parametri è uno scenario. Ogni scenario ha il suo foglio di calcolo (S1…S5).
A10: 3. Il foglio Confronto mette i risultati uno accanto all'altro. Il foglio Unitaria mostra l'economia per ordine e per cliente.
A12: Colori
A13: Testo blu su fondo giallo: valore inserito a mano, da discutere · Testo nero: formula · Testo verde: collegamento a un altro foglio
A15: Convenzioni
A16: Mese 1 = primo mese dopo la chiusura della raccolta. Importi in euro. Le spese di progetto sono al netto dell'IVA; l'IVA pagata
... A23: con un secondo modello scritto in Python (motore.py, nella stessa cartella). Le differenze sono sotto un centesimo.

Sheet Confronto
A1: Confronto fra scenari
A2: Tutti i valori sono collegamenti ai fogli di scenario: cambiano quando cambiano i Parametri.
A4: Risultato | B4: Base | C4: Lancio ritardato | D4: Avverso senza arresto | E4: Avverso con arresto | F4: Tutto insieme
A5: Cassa minima | B5: ='S1 Base'!$C$373 | C5: ='S2 Ritardo'!$C$373 | D5: ='S3 Avverso'!$C$373 | E5: ='S4 Avverso+arresto'!$C$373 | F5: ='S5 Tutto insieme'!$C$373
A6: Mese della cassa minima | B6: ='S1 Base'!$C$374 | C6: ='S2 Ritardo'!$C$374 | D6: ='S3 Avverso'!$C$374 | E6: ='S4 Avverso+arresto'!$C$374 | F6: ='S5 Tutto insieme'!$C$374
A7: Capitale assorbito fino al minimo | B7: ='S1 Base'!$C$375 | C7: ='S2 Ritardo'!$C$375 | D7: ='S3 Avverso'!$C$375 | E7: ='S4 Avverso+arresto'!$C$375 | F7: ='S5 Tutto insieme'!$C$375
A8: Cassa al mese 24 | B8: ='S1 Base'!$C$376 | C8: ='S2 Ritardo'!$C$376 | D8: ='S3 Avverso'!$C$376 | E8: ='S4 Avverso+arresto'!$C$376 | F8: ='S5 Tutto insieme'!$C$376
A9: Cassa al mese 30 | B9: ='S1 Base'!$C$377 | C9: ='S2 Ritardo'!$C$377 | D9: ='S3 Avverso'!$C$377 | E9: ='S4 Avverso+arresto'!$C$377 | F9: ='S5 Tutto insieme'!$C$377
A10: Nuovi clienti fino al mese 30 | B10: ='S1 Base'!$C$378 | C10: ='S2 Ritardo'!$C$378 | D10: ='S3 Avverso'!$C$378 | E10: ='S4 Avverso+arresto'!$C$378 | F10: ='S5 Tutto insieme'!$C$378
A11: di cui da pubblicità | B11: ='S1 Base'!$C$379 | C11: ='S2 Ritardo'!$C$379 | D11: ='S3 Avverso'!$C$379 | E11: ='S4 Avverso+arresto'!$C$379 | F11: ='S5 Tutto insieme'!$C$379
A12: Pubblicità fino al mese 30 | B12: ='S1 Base'!$C$380 | C12: ='S2 Ritardo'!$C$380 | D12: ='S3 Avverso'!$C$380 | E12: ='S4 Avverso+arresto'!$C$380 | F12: ='S5 Tutto insieme'!$C$380
A13: Ricavi netti fino al mese 30 | B13: ='S1 Base'!$C$381 | C13: ='S2 Ritardo'!$C$381 | D13: ='S3 Avverso'!$C$381 | E13: ='S4 Avverso+arresto'!$C$381 | F13: ='S5 Tutto insieme'!$C$381
A14: Rimborsi di garanzia pagati | B14: ='S1 Base'!$C$382 | C14: ='S2 Ritardo'!$C$382 | D14: ='S3 Avverso'!$C$382 | E14: ='S4 Avverso+arresto'!$C$382 | F14: ='S5 Tutto insieme'!$C$382
A15: Esposizione di garanzia massima | B15: ='S1 Base'!$C$385 | C15: ='S2 Ritardo'!$C$385 | D15: ='S3 Avverso'!$C$385 | E15: ='S4 Avverso+arresto'!$C$385 | F15: ='S5 Tutto insieme'!$C$385
A16: Credito IVA massimo | B16: ='S1 Base'!$C$384 | C16: ='S2 Ritardo'!$C$384 | D16: ='S3 Avverso'!$C$384 | E16: ='S4 Avverso+arresto'!$C$384 | F16: ='S5 Tutto insieme'!$C$384
A17: Lotti di produzione ordinati | B17: ='S1 Base'!$C$383 | C17: ='S2 Ritardo'!$C$383 | D17: ='S3 Avverso'!$C$383 | E17: ='S4 Avverso+arresto'!$C$383 | F17: ='S5 Tutto insieme'!$C$383
A18: Contribuzione media del primo ordine | B18: ='S1 Base'!$C$390 | C18: ='S2 Ritardo'!$C$390 | D18: ='S3 Avverso'!$C$390 | E18: ='S4 Avverso+arresto'!$C$390 | F18: ='S5 Tutto insieme'!$C$390
A19: Valore del cliente medio a 12 mesi | B19: ='S1 Base'!$C$387 | C19: ='S2 Ritardo'!$C$387 | D19: ='S3 Avverso'!$C$387 | E19: ='S4 Avverso+arresto'!$C$387 | F19: ='S5 Tutto insieme'!$C$387
A20: Valore del cliente medio a 24 mesi | B20: ='S1 Base'!$C$388 | C20: ='S2 Ritardo'!$C$388 | D20: ='S3 Avverso'!$C$388 | E20: ='S4 Avverso+arresto'!$C$388 | F20: ='S5 Tutto insieme'!$C$388
A21: CAC massimo (regola 2:1 sul valore a 24 mesi) | B21: ='S1 Base'!$C$389 | C21: ='S2 Ritardo'!$C$389 | D21: ='S3 Avverso'!$C$389 | E21: ='S4 Avverso+arresto'!$C$389 | F21: ='S5 Tutto insieme'!$C$389

Sheet Unitaria
A1: Economia per ordine e per cliente (scenario base)
A2: Collegata al foglio S1 Base. Per altri valori si cambiano i Parametri.
A4: Per ordine (successivo) | B4: Percorso 6 | C4: Percorso 3 | D4: Abbonamento | E4: Singolo
A5: Prezzo pagato | B5: ='S1 Base'!C76 | C5: ='S1 Base'!D76 | D5: ='S1 Base'!E76 | E5: ='S1 Base'!F76
A6: Ricavo netto IVA | B6: ='S1 Base'!C77 | C6: ='S1 Base'!D77 | D6: ='S1 Base'!E77 | E6: ='S1 Base'!F77
A7: Costo del prodotto | B7: ='S1 Base'!C78 | C7: ='S1 Base'!D78 | D7: ='S1 Base'!E78 | E7: ='S1 Base'!F78
A8: Logistica | B8: ='S1 Base'!C79 | C8: ='S1 Base'!D79 | D8: ='S1 Base'!E79 | E8: ='S1 Base'!F79
A9: Commissione di incasso | B9: ='S1 Base'!C80 | C9: ='S1 Base'!D80 | D9: ='S1 Base'!E80 | E9: ='S1 Base'!F80
A10: Assistenza e resi ordinari | B10: ='S1 Base'!C81 | C10: ='S1 Base'!D81 | D10: ='S1 Base'!E81 | E10: ='S1 Base'!F81
A11: Contribuzione | B11: ='S1 Base'!C82 | C11: ='S1 Base'!D82 | D11: ='S1 Base'!E82 | E11: ='S1 Base'!F82
A12: Contribuzione in % del ricavo netto | B12: =B11/B6 | C12: =C11/C6 | D12: =D11/D6 | E12: =E11/E6
A13: Contribuzione in % del prezzo pagato | B13: =B11/B5 | C13: =C11/C5 | D13: =D11/D5 | E13: =E11/E5
A15: Valore per cliente (contribuzione cumulata) | B15: Percorso 6 | C15: Percorso 3 | D15: Abbonamento | E15: Singolo | F15: Cliente medio
A16: entro 1 mesi | B16: ='S1 Base'!C98 | C16: ='S1 Base'!C99 | D16: ='S1 Base'!C100 | E16: ='S1 Base'!C101 | F16: ='S1 Base'!C102
A17: entro 3 mesi | B17: ='S1 Base'!E98 | C17: ='S1 Base'!E99 | D17: ='S1 Base'!E100 | E17: ='S1 Base'!E101 | F17: ='S1 Base'!E102
A18: entro 6 mesi | B18: ='S1 Base'!H98 | C18: ='S1 Base'!H99 | D18: ='S1 Base'!H100 | E18: ='S1 Base'!H101 | F18: ='S1 Base'!H102
A19: entro 12 mesi | B19: ='S1 Base'!N98 | C19: ='S1 Base'!N99 | D19: ='S1 Base'!N100 | E19: ='S1 Base'!N101 | F19: ='S1 Base'!N102
A20: entro 24 mesi | B20: ='S1 Base'!Z98 | C20: ='S1 Base'!Z99 | D20: ='S1 Base'!Z100 | E20: ='S1 Base'!Z101 | F20: ='S1 Base'!Z102
A21: entro 36 mesi | B21: ='S1 Base'!AL98 | C21: ='S1 Base'!AL99 | D21: ='S1 Base'!AL100 | E21: ='S1 Base'!AL101 | F21: ='S1 Base'!AL102
A23: Percorso da 6: contribuzione del primo ordine al variare dei rimborsi
A24: Rimborsi sul totale | B24: Contribuzione | C24: Dopo CAC 50 | D24: Dopo CAC 60 | E24: Dopo CAC 80
A25: 0.05 | B25: ='S1 Base'!$H$82-A25*'S1 Base'!$H$77 | C25: =B25-50 | D25: =B25-60 | E25: =B25-80
A26: 0.121 | B26: ='S1 Base'!$H$82-A26*'S1 Base'!$H$77 | C26: =B26-50 | D26: =B26-60 | E26: =B26-80
A27: 0.2 | B27: ='S1 Base'!$H$82-A27*'S1 Base'!$H$77 | C27: =B27-50 | D27: =B27-60 | E27: =B27-80
A28: 0.3 | B28: ='S1 Base'!$H$82-A28*'S1 Base'!$H$77 | C28: =B28-50 | D28: =B28-60 | E28: =B28-80
A29: Pareggio sul primo ordine | C29: =('S1 Base'!$H$82-50)/'S1 Base'!$H$77 | D29: =('S1 Base'!$H$82-60)/'S1 Base'!$H$77 | E29: =('S1 Base'!$H$82-80)/'S1 Base'!$H$77
A31: Sensibilità al costo industriale (tutte le altre ipotesi del base)
A32: Costo per flacone | B32: Valore a 24 mesi | C32: CAC massimo 2:1
A33: 5.35 | B33: ='S1 Base'!$Z$102+('S1 Base'!$C$7-A33)*('S1 Base'!$C$8*SUM('S1 Base'!$C$93:$Z$93)*6+'S1 Base'!$C$9*SUM('S1 Base'!$C$95:$Z$95)*3+'S1 Base'!$C$10*SUM('S1 Base'!$C$96:$Z$96)*1+'S1 Base'!$C$11*SUM('S1 Base'!$C$97:$Z$97)*1) | C33: =B33/2
A34: 8.5 | B34: ='S1 Base'!$Z$102+('S1 Base'!$C$7-A34)*('S1 Base'!$C$8*SUM('S1 Base'!$C$93:$Z$93)*6+'S1 Base'!$C$9*SUM('S1 Base'!$C$95:$Z$95)*3+'S1 Base'!$C$10*SUM('S1 Base'!$C$96:$Z$96)*1+'S1 Base'!$C$11*SUM('S1 Base'!$C$97:$Z$97)*1) | C34: =B34/2
A35: 11.9 | B35: ='S1 Base'!$Z$102+('S1 Base'!$C$7-A35)*('S1 Base'!$C$8*SUM('S1 Base'!$C$93:$Z$93)*6+'S1 Base'!$C$9*SUM('S1 Base'!$C$95:$Z$95)*3+'S1 Base'!$C$10*SUM('S1 Base'!$C$96:$Z$96)*1+'S1 Base'!$C$11*SUM('S1 Base'!$C$97:$Z$97)*1) | C35: =B35/2

Sheet Parametri
A1: Parametri del modello
A2: Blu su giallo: da discutere e modificare. Una colonna per scenario.
A4: Parametro | B4: Unità | C4: Nota | D4: Base | E4: Lancio ritardato | F4: Avverso senza arresto | G4: Avverso con arresto | H4: Tutto insieme
A5: Mese del lancio | B5: mese | C5: Primo mese di vendita dopo la chiusura della raccolta | D5: 16 | E5: 20 | F5: 16 | G5: 16 | H5: 20
A6: Costo industriale per flacone | B6: € | C6: Stima centrale 8,50; alta 11,90 (capitolo 08) | D6: 8.5 | E6: 8.5 | F6: 11.9 | G6: 11.9 | H6: 11.9
A7: Quota nuovi clienti: percorso da 6 | B7: % | C7: IPOTESI. La più delicata per la cassa | D7: 0.25 | E7: 0.25 | F7: 0.25 | G7: 0.25 | H7: 0.25
A8: Quota nuovi clienti: percorso da 3 | B8: % | C8: IPOTESI | D8: 0.1 | E8: 0.1 | F8: 0.1 | G8: 0.1 | H8: 0.1
A9: Quota nuovi clienti: abbonamento | B9: % | C9: IPOTESI | D9: 0.45 | E9: 0.45 | F9: 0.45 | G9: 0.45 | H9: 0.45
A10: Quota nuovi clienti: flacone singolo | B10: % | C10: IPOTESI. Le quattro quote devono sommare a 100% | D10: 0.2 | E10: 0.2 | F10: 0.2 | G10: 0.2 | H10: 0.2
A11: Percorso da 6: quota che lo completa | B11: % | C11: IPOTESI. Solo chi completa può chiedere la garanzia | D11: 0.55 | E11: 0.55 | F11: 0.55 | G11: 0.55 | H11: 0.55
A12: Percorso da 6: chi completa e chiede il rimborso | B12: % | C12: IPOTESI. Rimborsi sul totale = completamento × questa quota | D12: 0.22 | E12: 0.22 | F12: 0.36 | G12: 0.36 | H12: 0.36
A13: Percorso da 6: riacquisto di chi completa senza rimborso | B13: % | C13: IPOTESI. Nuovo percorso da 6, senza garanzia | D13: 0.45 | E13: 0.45 | F13: 0.35 | G13: 0.35 | H13: 0.35
A14: Percorso da 6: riacquisti successivi | B14: % | C14: IPOTESI | D14: 0.6 | E14: 0.6 | F14: 0.6 | G14: 0.6 | H14: 0.6
A15: Percorso da 3: riacquisto a 3 mesi | B15: % | C15: IPOTESI | D15: 0.35 | E15: 0.35 | F15: 0.25 | G15: 0.25 | H15: 0.25
A16: Percorso da 3: riacquisti successivi | B16: % | C16: IPOTESI | D16: 0.55 | E16: 0.55 | F16: 0.55 | G16: 0.55 | H16: 0.55
... A26: Pubblicità tranche 1 (totale) | B26: € | C26: Prima coorte | D26: 10000 | E26: 10000 | F26: 10000 | G26: 10000 | H26: 10000
A27: Tranche 1: durata | B27: mesi | D27: 2 | E27: 2 | F27: 2 | G27: 2 | H27: 2
A28: CAC pubblicitario tranche 1 | B28: € | C28: IPOTESI. Avverso = base × 1,4 | D28: 50 | E28: 50 | F28: 70 | G28: 70 | H28: 70
A29: Pubblicità tranche 2 (totale) | B29: € | C29: Replica | D29: 20000 | E29: 20000 | F29: 20000 | G29: 20000 | H29: 20000
A30: Tranche 2: durata | B30: mesi | D30: 3 | E30: 3 | F30: 3 | G30: 3 | H30: 3
A31: CAC pubblicitario tranche 2 | B31: € | C31: IPOTESI | D31: 50 | E31: 50 | F31: 70 | G31: 70 | H31: 70
A32: Pubblicità tranche 3 (totale) | B32: € | C32: Liberata solo se passa la verifica. 0 = regola di arresto applicata | D32: 30000 | E32: 30000 | F32: 30000 | G32: 0 | H32: 30000
A33: Tranche 3: durata | B33: mesi | D33: 4 | E33: 4 | F33: 4 | G33: 4 | H33: 4
A34: CAC pubblicitario tranche 3 (marginale) | B34: € | C34: IPOTESI. Più spesa, clienti più cari | D34: 55 | E34: 55 | F34: 77 | G34: 77 | H34: 77
A35: Pubblicità mensile dopo le tranche | B35: €/mese | C35: Finanziata dalla cassa | D35: 5000 | E35: 5000 | F35: 5000 | G35: 0 | H35: 5000
A36: CAC dopo le tranche | B36: € | C36: IPOTESI | D36: 55 | E36: 55 | F36: 77 | G36: 77 | H36: 77
A37: Creatività e gestione campagne | B37: €/mese | C37: Nei mesi con pubblicità. Differenza fra CAC pubblicitario e complessivo | D37: 600 | E37: 600 | F37: 600 | G37: 600 | H37: 600
A38: Ciclo di laboratorio aggiuntivo, mese 10 | B38: € | C38: Solo negli scenari con ritardo | D38: 0 | E38: 6000 | F38: 0 | G38: 0 | H38: 6000
A39: Ciclo di laboratorio aggiuntivo, mese 11 | B39: € | D39: 0 | E39: 6000 | F39: 0 | G39: 0 | H39: 6000
A40: Capitale versato al mese 1 | B40: € | C40: Per simulare due tranche: 100.000 qui e 150.000 sotto | D40: 250000 | E40: 250000 | F40: 250000 | G40: 250000 | H40: 250000
A41: Mese della seconda tranche di capitale | B41: mese | D41: 10 | E41: 10 | F41: 10 | G41: 10 | H41: 10
A42: Seconda tranche di capitale | B42: € | D42: 0 | E42: 0 | F42: 0 | G42: 0 | H42: 0
A44: Costanti, uguali per tutti gli scenari
A45: Aliquota IVA | B45: % | D45: 0.22
A46: Prezzo percorso da 6 flaconi | B46: € IVA incl. | D46: 279
A47: Prezzo percorso da 3 flaconi | B47: € IVA incl. | D47: 149
A48: Prezzo abbonamento, ogni 28 giorni | B48: € IVA incl. | C48: Consegna ogni 28 giorni: 57 mL utili a 2 mL/giorno | D48: 49
A49: Prezzo flacone singolo | B49: € IVA incl. | D49: 59
A50: Flaconi: percorso da 6 | B50: n | D50: 6
A51: Flaconi: percorso da 3 | B51: n | D51: 3
...

Sheet Progetto
A1: Costi di progetto prima del lancio
A2: Importi al netto dell'IVA. 'Legato al lancio' = sì: la voce si sposta se il lancio slitta (mese effettivo = mese base + lancio − 16). Quota IVA = parte dell'importo su cui si paga IVA italiana.
A4: Voce | B4: Mese base | C4: Legato al lancio | D4: Importo € | E4: Quota IVA | F4: Tappa
A5: Costituzione della società | B5: 1 | C5: no | D5: 3500 | E5: 0.6 | F5: 1
A6: Patti parasociali e documenti dell'investimento | B6: 1 | C6: no | D6: 2500 | E6: 1 | F6: 1
A7: Parere brevettuale sulla formula C | B7: 2 | C7: no | D7: 3500 | E7: 1 | F7: 1
A8: Deposito del marchio UE | B8: 2 | C8: no | D8: 1500 | E8: 0.3 | F8: 1
A9: Interviste: incentivi e reclutamento | B9: 2 | C9: no | D9: 750 | E9: 0 | F9: 1
A10: Interviste: incentivi e reclutamento | B10: 3 | C10: no | D10: 750 | E10: 0 | F10: 1
A11: Laboratorio: fattibilità | B11: 4 | C11: no | D11: 3000 | E11: 1 | F11: 2
A12: Laboratorio: metodi analitici, acconto | B12: 5 | C12: no | D12: 5000 | E12: 1 | F12: 2
A13: Laboratorio: metodi analitici, saldo | B13: 7 | C13: no | D13: 5000 | E13: 1 | F13: 2
A14: Laboratorio: micro-prove e solubilità | B14: 5 | C14: no | D14: 4000 | E14: 1 | F14: 2
A15: Laboratorio: micro-prove e solubilità | B15: 6 | C15: no | D15: 4000 | E15: 1 | F15: 2
A16: Laboratorio: micro-prove e solubilità | B16: 7 | C16: no | D16: 4000 | E16: 1 | F16: 2
... A42: Lotto pilota e trasferimento di scala | B42: 12 | C42: sì | D42: 8500 | E42: 1 | F42: 3
A43: Totale | D43: =SUM(D5:D42)
A45: Tappa 1 | D45: =SUMIF(F5:F42,1,D5:D42)
A46: Tappa 2 | D46: =SUMIF(F5:F42,2,D5:D42)
A47: Tappa 3 | D47: =SUMIF(F5:F42,3,D5:D42)
A48: Il ciclo di laboratorio aggiuntivo degli scenari con ritardo è in Parametri, non qui.

Sheet S1 Base
A1: Scenario 1: Base
A2: Indice dello scenario (colonna di Parametri) | C2: 1
A5: Parametri dello scenario (da Parametri)
A6: Mese del lancio | B6: mese | C6: =INDEX(Parametri!$D$5:$H$5,1,$C$2)
A7: Costo industriale per flacone | B7: € | C7: =INDEX(Parametri!$D$6:$H$6,1,$C$2)
A8: Quota nuovi clienti: percorso da 6 | B8: % | C8: =INDEX(Parametri!$D$7:$H$7,1,$C$2)
A9: Quota nuovi clienti: percorso da 3 | B9: % | C9: =INDEX(Parametri!$D$8:$H$8,1,$C$2)
A10: Quota nuovi clienti: abbonamento | B10: % | C10: =INDEX(Parametri!$D$9:$H$9,1,$C$2)
A11: Quota nuovi clienti: flacone singolo | B11: % | C11: =INDEX(Parametri!$D$10:$H$10,1,$C$2)
A12: Percorso da 6: quota che lo completa | B12: % | C12: =INDEX(Parametri!$D$11:$H$11,1,$C$2)
A13: Percorso da 6: chi completa e chiede il rimborso | B13: % | C13: =INDEX(Parametri!$D$12:$H$12,1,$C$2)
A14: Percorso da 6: riacquisto di chi completa senza rimborso | B14: % | C14: =INDEX(Parametri!$D$13:$H$13,1,$C$2)
A15: Percorso da 6: riacquisti successivi | B15: % | C15: =INDEX(Parametri!$D$14:$H$14,1,$C$2)
A16: Percorso da 3: riacquisto a 3 mesi | B16: % | C16: =INDEX(Parametri!$D$15:$H$15,1,$C$2)
A17: Percorso da 3: riacquisti successivi | B17: % | C17: =INDEX(Parametri!$D$16:$H$16,1,$C$2)
A18: Abbonamento: rinnovo dopo il 1° invio | B18: % | C18: =INDEX(Parametri!$D$17:$H$17,1,$C$2)
A19: Abbonamento: rinnovo dopo il 2° invio | B19: % | C19: =INDEX(Parametri!$D$18:$H$18,1,$C$2)
A20: Abbonamento: rinnovo dopo il 3° invio | B20: % | C20: =INDEX(Parametri!$D$19:$H$19,1,$C$2)
A21: Abbonamento: rinnovo dopo il 4° invio | B21: % | C21: =INDEX(Parametri!$D$20:$H$20,1,$C$2)
A22: Abbonamento: rinnovo dopo il 5° invio | B22: % | C22: =INDEX(Parametri!$D$21:$H$21,1,$C$2)
A23: Abbonamento: rinnovo dal 6° invio in poi | B23: % | C23: =INDEX(Parametri!$D$22:$H$22,1,$C$2)
A24: Flacone singolo: probabilità di un nuovo acquisto | B24: % | C24: =INDEX(Parametri!$D$23:$H$23,1,$C$2)
A25: Sconto medio sul primo ordine | B25: % | C25: =INDEX(Parametri!$D$24:$H$24,1,$C$2)
A26: Clienti da canali non pagati, al mese | B26: clienti | C26: =INDEX(Parametri!$D$25:$H$25,1,$C$2)
A27: Pubblicità tranche 1 (totale) | B27: € | C27: =INDEX(Parametri!$D$26:$H$26,1,$C$2)
A28: Tranche 1: durata | B28: mesi | C28: =INDEX(Parametri!$D$27:$H$27,1,$C$2)
A29: CAC pubblicitario tranche 1 | B29: € | C29: =INDEX(Parametri!$D$28:$H$28,1,$C$2)
A30: Pubblicità tranche 2 (totale) | B30: € | C30: =INDEX(Parametri!$D$29:$H$29,1,$C$2)
A31: Tranche 2: durata | B31: mesi | C31: =INDEX(Parametri!$D$30:$H$30,1,$C$2)
A32: CAC pubblicitario tranche 2 | B32: € | C32: =INDEX(Parametri!$D$31:$H$31,1,$C$2)
A33: Pubblicità tranche 3 (totale) | B33: € | C33: =INDEX(Parametri!$D$32:$H$32,1,$C$2)
A34: Tranche 3: durata | B34: mesi | C34: =INDEX(Parametri!$D$33:$H$33,1,$C$2)
A35: CAC pubblicitario tranche 3 (marginale) | B35: € | C35: =INDEX(Parametri!$D$34:$H$34,1,$C$2)
A36: Pubblicità mensile dopo le tranche | B36: €/mese | C36: =INDEX(Parametri!$D$35:$H$35,1,$C$2)
A37: CAC dopo le tranche | B37: € | C37: =INDEX(Parametri!$D$36:$H$36,1,$C$2)
A38: Creatività e gestione campagne | B38: €/mese | C38: =INDEX(Parametri!$D$37:$H$37,1,$C$2)
A39: Ciclo di laboratorio aggiuntivo, mese 10 | B39: € | C39: =INDEX(Parametri!$D$38:$H$38,1,$C$2)
A40: Ciclo di laboratorio aggiuntivo, mese 11 | B40: € | C40: =INDEX(Parametri!$D$39:$H$39,1,$C$2)
A41: Capitale versato al mese 1 | B41: € | C41: =INDEX(Parametri!$D$40:$H$40,1,$C$2)
A42: Mese della seconda tranche di capitale | B42: mese | C42: =INDEX(Parametri!$D$41:$H$41,1,$C$2)
...

Sheet S2 Ritardo
A1: Scenario 2: Lancio ritardato
A2: Indice dello scenario (colonna di Parametri) | C2: 2
A5: Parametri dello scenario (da Parametri)
A6: Mese del lancio | B6: mese | C6: =INDEX(Parametri!$D$5:$H$5,1,$C$2)
A7: Costo industriale per flacone | B7: € | C7: =INDEX(Parametri!$D$6:$H$6,1,$C$2)
A8: Quota nuovi clienti: percorso da 6 | B8: % | C8: =INDEX(Parametri!$D$7:$H$7,1,$C$2)
A9: Quota nuovi clienti: percorso da 3 | B9: % | C9: =INDEX(Parametri!$D$8:$H$8,1,$C$2)
A10: Quota nuovi clienti: abbonamento | B10: % | C10: =INDEX(Parametri!$D$9:$H$9,1,$C$2)
A11: Quota nuovi clienti: flacone singolo | B11: % | C11: =INDEX(Parametri!$D$10:$H$10,1,$C$2)
A12: Percorso da 6: quota che lo completa | B12: % | C12: =INDEX(Parametri!$D$11:$H$11,1,$C$2)
A13: Percorso da 6: chi completa e chiede il rimborso | B13: % | C13: =INDEX(Parametri!$D$12:$H$12,1,$C$2)
A14: Percorso da 6: riacquisto di chi completa senza rimborso | B14: % | C14: =INDEX(Parametri!$D$13:$H$13,1,$C$2)
A15: Percorso da 6: riacquisti successivi | B15: % | C15: =INDEX(Parametri!$D$14:$H$14,1,$C$2)
A16: Percorso da 3: riacquisto a 3 mesi | B16: % | C16: =INDEX(Parametri!$D$15:$H$15,1,$C$2)
A17: Percorso da 3: riacquisti successivi | B17: % | C17: =INDEX(Parametri!$D$16:$H$16,1,$C$2)
A18: Abbonamento: rinnovo dopo il 1° invio | B18: % | C18: =INDEX(Parametri!$D$17:$H$17,1,$C$2)
A19: Abbonamento: rinnovo dopo il 2° invio | B19: % | C19: =INDEX(Parametri!$D$18:$H$18,1,$C$2)
A20: Abbonamento: rinnovo dopo il 3° invio | B20: % | C20: =INDEX(Parametri!$D$19:$H$19,1,$C$2)
A21: Abbonamento: rinnovo dopo il 4° invio | B21: % | C21: =INDEX(Parametri!$D$20:$H$20,1,$C$2)
A22: Abbonamento: rinnovo dopo il 5° invio | B22: % | C22: =INDEX(Parametri!$D$21:$H$21,1,$C$2)
A23: Abbonamento: rinnovo dal 6° invio in poi | B23: % | C23: =INDEX(Parametri!$D$22:$H$22,1,$C$2)
A24: Flacone singolo: probabilità di un nuovo acquisto | B24: % | C24: =INDEX(Parametri!$D$23:$H$23,1,$C$2)
A25: Sconto medio sul primo ordine | B25: % | C25: =INDEX(Parametri!$D$24:$H$24,1,$C$2)
A26: Clienti da canali non pagati, al mese | B26: clienti | C26: =INDEX(Parametri!$D$25:$H$25,1,$C$2)
A27: Pubblicità tranche 1 (totale) | B27: € | C27: =INDEX(Parametri!$D$26:$H$26,1,$C$2)
A28: Tranche 1: durata | B28: mesi | C28: =INDEX(Parametri!$D$27:$H$27,1,$C$2)
A29: CAC pubblicitario tranche 1 | B29: € | C29: =INDEX(Parametri!$D$28:$H$28,1,$C$2)
A30: Pubblicità tranche 2 (totale) | B30: € | C30: =INDEX(Parametri!$D$29:$H$29,1,$C$2)
A31: Tranche 2: durata | B31: mesi | C31: =INDEX(Parametri!$D$30:$H$30,1,$C$2)
A32: CAC pubblicitario tranche 2 | B32: € | C32: =INDEX(Parametri!$D$31:$H$31,1,$C$2)
A33: Pubblicità tranche 3 (totale) | B33: € | C33: =INDEX(Parametri!$D$32:$H$32,1,$C$2)
A34: Tranche 3: durata | B34: mesi | C34: =INDEX(Parametri!$D$33:$H$33,1,$C$2)
A35: CAC pubblicitario tranche 3 (marginale) | B35: € | C35: =INDEX(Parametri!$D$34:$H$34,1,$C$2)
A36: Pubblicità mensile dopo le tranche | B36: €/mese | C36: =INDEX(Parametri!$D$35:$H$35,1,$C$2)
A37: CAC dopo le tranche | B37: € | C37: =INDEX(Parametri!$D$36:$H$36,1,$C$2)
A38: Creatività e gestione campagne | B38: €/mese | C38: =INDEX(Parametri!$D$37:$H$37,1,$C$2)
A39: Ciclo di laboratorio aggiuntivo, mese 10 | B39: € | C39: =INDEX(Parametri!$D$38:$H$38,1,$C$2)
A40: Ciclo di laboratorio aggiuntivo, mese 11 | B40: € | C40: =INDEX(Parametri!$D$39:$H$39,1,$C$2)
A41: Capitale versato al mese 1 | B41: € | C41: =INDEX(Parametri!$D$40:$H$40,1,$C$2)
A42: Mese della seconda tranche di capitale | B42: mese | C42: =INDEX(Parametri!$D$41:$H$41,1,$C$2)
...

Sheet S3 Avverso
A1: Scenario 3: Avverso senza arresto
A2: Indice dello scenario (colonna di Parametri) | C2: 3
A5: Parametri dello scenario (da Parametri)
A6: Mese del lancio | B6: mese | C6: =INDEX(Parametri!$D$5:$H$5,1,$C$2)
A7: Costo industriale per flacone | B7: € | C7: =INDEX(Parametri!$D$6:$H$6,1,$C$2)
A8: Quota nuovi clienti: percorso da 6 | B8: % | C8: =INDEX(Parametri!$D$7:$H$7,1,$C$2)
A9: Quota nuovi clienti: percorso da 3 | B9: % | C9: =INDEX(Parametri!$D$8:$H$8,1,$C$2)
A10: Quota nuovi clienti: abbonamento | B10: % | C10: =INDEX(Parametri!$D$9:$H$9,1,$C$2)
A11: Quota nuovi clienti: flacone singolo | B11: % | C11: =INDEX(Parametri!$D$10:$H$10,1,$C$2)
A12: Percorso da 6: quota che lo completa | B12: % | C12: =INDEX(Parametri!$D$11:$H$11,1,$C$2)
A13: Percorso da 6: chi completa e chiede il rimborso | B13: % | C13: =INDEX(Parametri!$D$12:$H$12,1,$C$2)
A14: Percorso da 6: riacquisto di chi completa senza rimborso | B14: % | C14: =INDEX(Parametri!$D$13:$H$13,1,$C$2)
A15: Percorso da 6: riacquisti successivi | B15: % | C15: =INDEX(Parametri!$D$14:$H$14,1,$C$2)
A16: Percorso da 3: riacquisto a 3 mesi | B16: % | C16: =INDEX(Parametri!$D$15:$H$15,1,$C$2)
A17: Percorso da 3: riacquisti successivi | B17: % | C17: =INDEX(Parametri!$D$16:$H$16,1,$C$2)
A18: Abbonamento: rinnovo dopo il 1° invio | B18: % | C18: =INDEX(Parametri!$D$17:$H$17,1,$C$2)
A19: Abbonamento: rinnovo dopo il 2° invio | B19: % | C19: =INDEX(Parametri!$D$18:$H$18,1,$C$2)
A20: Abbonamento: rinnovo dopo il 3° invio | B20: % | C20: =INDEX(Parametri!$D$19:$H$19,1,$C$2)
A21: Abbonamento: rinnovo dopo il 4° invio | B21: % | C21: =INDEX(Parametri!$D$20:$H$20,1,$C$2)
A22: Abbonamento: rinnovo dopo il 5° invio | B22: % | C22: =INDEX(Parametri!$D$21:$H$21,1,$C$2)
A23: Abbonamento: rinnovo dal 6° invio in poi | B23: % | C23: =INDEX(Parametri!$D$22:$H$22,1,$C$2)
A24: Flacone singolo: probabilità di un nuovo acquisto | B24: % | C24: =INDEX(Parametri!$D$23:$H$23,1,$C$2)
A25: Sconto medio sul primo ordine | B25: % | C25: =INDEX(Parametri!$D$24:$H$24,1,$C$2)
A26: Clienti da canali non pagati, al mese | B26: clienti | C26: =INDEX(Parametri!$D$25:$H$25,1,$C$2)
A27: Pubblicità tranche 1 (totale) | B27: € | C27: =INDEX(Parametri!$D$26:$H$26,1,$C$2)
A28: Tranche 1: durata | B28: mesi | C28: =INDEX(Parametri!$D$27:$H$27,1,$C$2)
A29: CAC pubblicitario tranche 1 | B29: € | C29: =INDEX(Parametri!$D$28:$H$28,1,$C$2)
A30: Pubblicità tranche 2 (totale) | B30: € | C30: =INDEX(Parametri!$D$29:$H$29,1,$C$2)
A31: Tranche 2: durata | B31: mesi | C31: =INDEX(Parametri!$D$30:$H$30,1,$C$2)
A32: CAC pubblicitario tranche 2 | B32: € | C32: =INDEX(Parametri!$D$31:$H$31,1,$C$2)
A33: Pubblicità tranche 3 (totale) | B33: € | C33: =INDEX(Parametri!$D$32:$H$32,1,$C$2)
A34: Tranche 3: durata | B34: mesi | C34: =INDEX(Parametri!$D$33:$H$33,1,$C$2)
A35: CAC pubblicitario tranche 3 (marginale) | B35: € | C35: =INDEX(Parametri!$D$34:$H$34,1,$C$2)
A36: Pubblicità mensile dopo le tranche | B36: €/mese | C36: =INDEX(Parametri!$D$35:$H$35,1,$C$2)
A37: CAC dopo le tranche | B37: € | C37: =INDEX(Parametri!$D$36:$H$36,1,$C$2)
A38: Creatività e gestione campagne | B38: €/mese | C38: =INDEX(Parametri!$D$37:$H$37,1,$C$2)
A39: Ciclo di laboratorio aggiuntivo, mese 10 | B39: € | C39: =INDEX(Parametri!$D$38:$H$38,1,$C$2)
A40: Ciclo di laboratorio aggiuntivo, mese 11 | B40: € | C40: =INDEX(Parametri!$D$39:$H$39,1,$C$2)
A41: Capitale versato al mese 1 | B41: € | C41: =INDEX(Parametri!$D$40:$H$40,1,$C$2)
A42: Mese della seconda tranche di capitale | B42: mese | C42: =INDEX(Parametri!$D$41:$H$41,1,$C$2)
...

Sheet S4 Avverso+arresto
A1: Scenario 4: Avverso con arresto
A2: Indice dello scenario (colonna di Parametri) | C2: 4
A5: Parametri dello scenario (da Parametri)
A6: Mese del lancio | B6: mese | C6: =INDEX(Parametri!$D$5:$H$5,1,$C$2)
A7: Costo industriale per flacone | B7: € | C7: =INDEX(Parametri!$D$6:$H$6,1,$C$2)
A8: Quota nuovi clienti: percorso da 6 | B8: % | C8: =INDEX(Parametri!$D$7:$H$7,1,$C$2)
A9: Quota nuovi clienti: percorso da 3 | B9: % | C9: =INDEX(Parametri!$D$8:$H$8,1,$C$2)
A10: Quota nuovi clienti: abbonamento | B10: % | C10: =INDEX(Parametri!$D$9:$H$9,1,$C$2)
A11: Quota nuovi clienti: flacone singolo | B11: % | C11: =INDEX(Parametri!$D$10:$H$10,1,$C$2)
A12: Percorso da 6: quota che lo completa | B12: % | C12: =INDEX(Parametri!$D$11:$H$11,1,$C$2)
A13: Percorso da 6: chi completa e chiede il rimborso | B13: % | C13: =INDEX(Parametri!$D$12:$H$12,1,$C$2)
A14: Percorso da 6: riacquisto di chi completa senza rimborso | B14: % | C14: =INDEX(Parametri!$D$13:$H$13,1,$C$2)
A15: Percorso da 6: riacquisti successivi | B15: % | C15: =INDEX(Parametri!$D$14:$H$14,1,$C$2)
A16: Percorso da 3: riacquisto a 3 mesi | B16: % | C16: =INDEX(Parametri!$D$15:$H$15,1,$C$2)
A17: Percorso da 3: riacquisti successivi | B17: % | C17: =INDEX(Parametri!$D$16:$H$16,1,$C$2)
A18: Abbonamento: rinnovo dopo il 1° invio | B18: % | C18: =INDEX(Parametri!$D$17:$H$17,1,$C$2)
A19: Abbonamento: rinnovo dopo il 2° invio | B19: % | C19: =INDEX(Parametri!$D$18:$H$18,1,$C$2)
A20: Abbonamento: rinnovo dopo il 3° invio | B20: % | C20: =INDEX(Parametri!$D$19:$H$19,1,$C$2)
A21: Abbonamento: rinnovo dopo il 4° invio | B21: % | C21: =INDEX(Parametri!$D$20:$H$20,1,$C$2)
A22: Abbonamento: rinnovo dopo il 5° invio | B22: % | C22: =INDEX(Parametri!$D$21:$H$21,1,$C$2)
A23: Abbonamento: rinnovo dal 6° invio in poi | B23: % | C23: =INDEX(Parametri!$D$22:$H$22,1,$C$2)
A24: Flacone singolo: probabilità di un nuovo acquisto | B24: % | C24: =INDEX(Parametri!$D$23:$H$23,1,$C$2)
A25: Sconto medio sul primo ordine | B25: % | C25: =INDEX(Parametri!$D$24:$H$24,1,$C$2)
A26: Clienti da canali non pagati, al mese | B26: clienti | C26: =INDEX(Parametri!$D$25:$H$25,1,$C$2)
A27: Pubblicità tranche 1 (totale) | B27: € | C27: =INDEX(Parametri!$D$26:$H$26,1,$C$2)
A28: Tranche 1: durata | B28: mesi | C28: =INDEX(Parametri!$D$27:$H$27,1,$C$2)
A29: CAC pubblicitario tranche 1 | B29: € | C29: =INDEX(Parametri!$D$28:$H$28,1,$C$2)
A30: Pubblicità tranche 2 (totale) | B30: € | C30: =INDEX(Parametri!$D$29:$H$29,1,$C$2)
A31: Tranche 2: durata | B31: mesi | C31: =INDEX(Parametri!$D$30:$H$30,1,$C$2)
A32: CAC pubblicitario tranche 2 | B32: € | C32: =INDEX(Parametri!$D$31:$H$31,1,$C$2)
A33: Pubblicità tranche 3 (totale) | B33: € | C33: =INDEX(Parametri!$D$32:$H$32,1,$C$2)
A34: Tranche 3: durata | B34: mesi | C34: =INDEX(Parametri!$D$33:$H$33,1,$C$2)
A35: CAC pubblicitario tranche 3 (marginale) | B35: € | C35: =INDEX(Parametri!$D$34:$H$34,1,$C$2)
A36: Pubblicità mensile dopo le tranche | B36: €/mese | C36: =INDEX(Parametri!$D$35:$H$35,1,$C$2)
A37: CAC dopo le tranche | B37: € | C37: =INDEX(Parametri!$D$36:$H$36,1,$C$2)
A38: Creatività e gestione campagne | B38: €/mese | C38: =INDEX(Parametri!$D$37:$H$37,1,$C$2)
A39: Ciclo di laboratorio aggiuntivo, mese 10 | B39: € | C39: =INDEX(Parametri!$D$38:$H$38,1,$C$2)
A40: Ciclo di laboratorio aggiuntivo, mese 11 | B40: € | C40: =INDEX(Parametri!$D$39:$H$39,1,$C$2)
A41: Capitale versato al mese 1 | B41: € | C41: =INDEX(Parametri!$D$40:$H$40,1,$C$2)
A42: Mese della seconda tranche di capitale | B42: mese | C42: =INDEX(Parametri!$D$41:$H$41,1,$C$2)
...

Sheet S5 Tutto insieme
A1: Scenario 5: Tutto insieme
A2: Indice dello scenario (colonna di Parametri) | C2: 5
A5: Parametri dello scenario (da Parametri)
A6: Mese del lancio | B6: mese | C6: =INDEX(Parametri!$D$5:$H$5,1,$C$2)
A7: Costo industriale per flacone | B7: € | C7: =INDEX(Parametri!$D$6:$H$6,1,$C$2)
A8: Quota nuovi clienti: percorso da 6 | B8: % | C8: =INDEX(Parametri!$D$7:$H$7,1,$C$2)
A9: Quota nuovi clienti: percorso da 3 | B9: % | C9: =INDEX(Parametri!$D$8:$H$8,1,$C$2)
A10: Quota nuovi clienti: abbonamento | B10: % | C10: =INDEX(Parametri!$D$9:$H$9,1,$C$2)
A11: Quota nuovi clienti: flacone singolo | B11: % | C11: =INDEX(Parametri!$D$10:$H$10,1,$C$2)
A12: Percorso da 6: quota che lo completa | B12: % | C12: =INDEX(Parametri!$D$11:$H$11,1,$C$2)
A13: Percorso da 6: chi completa e chiede il rimborso | B13: % | C13: =INDEX(Parametri!$D$12:$H$12,1,$C$2)
A14: Percorso da 6: riacquisto di chi completa senza rimborso | B14: % | C14: =INDEX(Parametri!$D$13:$H$13,1,$C$2)
A15: Percorso da 6: riacquisti successivi | B15: % | C15: =INDEX(Parametri!$D$14:$H$14,1,$C$2)
A16: Percorso da 3: riacquisto a 3 mesi | B16: % | C16: =INDEX(Parametri!$D$15:$H$15,1,$C$2)
A17: Percorso da 3: riacquisti successivi | B17: % | C17: =INDEX(Parametri!$D$16:$H$16,1,$C$2)
A18: Abbonamento: rinnovo dopo il 1° invio | B18: % | C18: =INDEX(Parametri!$D$17:$H$17,1,$C$2)
A19: Abbonamento: rinnovo dopo il 2° invio | B19: % | C19: =INDEX(Parametri!$D$18:$H$18,1,$C$2)
A20: Abbonamento: rinnovo dopo il 3° invio | B20: % | C20: =INDEX(Parametri!$D$19:$H$19,1,$C$2)
A21: Abbonamento: rinnovo dopo il 4° invio | B21: % | C21: =INDEX(Parametri!$D$20:$H$20,1,$C$2)
A22: Abbonamento: rinnovo dopo il 5° invio | B22: % | C22: =INDEX(Parametri!$D$21:$H$21,1,$C$2)
A23: Abbonamento: rinnovo dal 6° invio in poi | B23: % | C23: =INDEX(Parametri!$D$22:$H$22,1,$C$2)
A24: Flacone singolo: probabilità di un nuovo acquisto | B24: % | C24: =INDEX(Parametri!$D$23:$H$23,1,$C$2)
A25: Sconto medio sul primo ordine | B25: % | C25: =INDEX(Parametri!$D$24:$H$24,1,$C$2)
A26: Clienti da canali non pagati, al mese | B26: clienti | C26: =INDEX(Parametri!$D$25:$H$25,1,$C$2)
A27: Pubblicità tranche 1 (totale) | B27: € | C27: =INDEX(Parametri!$D$26:$H$26,1,$C$2)
A28: Tranche 1: durata | B28: mesi | C28: =INDEX(Parametri!$D$27:$H$27,1,$C$2)
A29: CAC pubblicitario tranche 1 | B29: € | C29: =INDEX(Parametri!$D$28:$H$28,1,$C$2)
A30: Pubblicità tranche 2 (totale) | B30: € | C30: =INDEX(Parametri!$D$29:$H$29,1,$C$2)
A31: Tranche 2: durata | B31: mesi | C31: =INDEX(Parametri!$D$30:$H$30,1,$C$2)
A32: CAC pubblicitario tranche 2 | B32: € | C32: =INDEX(Parametri!$D$31:$H$31,1,$C$2)
A33: Pubblicità tranche 3 (totale) | B33: € | C33: =INDEX(Parametri!$D$32:$H$32,1,$C$2)
A34: Tranche 3: durata | B34: mesi | C34: =INDEX(Parametri!$D$33:$H$33,1,$C$2)
A35: CAC pubblicitario tranche 3 (marginale) | B35: € | C35: =INDEX(Parametri!$D$34:$H$34,1,$C$2)
A36: Pubblicità mensile dopo le tranche | B36: €/mese | C36: =INDEX(Parametri!$D$35:$H$35,1,$C$2)
A37: CAC dopo le tranche | B37: € | C37: =INDEX(Parametri!$D$36:$H$36,1,$C$2)
A38: Creatività e gestione campagne | B38: €/mese | C38: =INDEX(Parametri!$D$37:$H$37,1,$C$2)
A39: Ciclo di laboratorio aggiuntivo, mese 10 | B39: € | C39: =INDEX(Parametri!$D$38:$H$38,1,$C$2)
A40: Ciclo di laboratorio aggiuntivo, mese 11 | B40: € | C40: =INDEX(Parametri!$D$39:$H$39,1,$C$2)
A41: Capitale versato al mese 1 | B41: € | C41: =INDEX(Parametri!$D$40:$H$40,1,$C$2)
A42: Mese della seconda tranche di capitale | B42: mese | C42: =INDEX(Parametri!$D$41:$H$41,1,$C$2)
...
